Workbook

Sheet Legend
A1: Bảng so sánh thí nghiệm — Lab Day 1
A2: Lưu file này thành experiments.xlsx. Mỗi lần chạy là một dòng ở sheet Experiments (số dòng tuỳ bạn, có sẵn 60 dòng). Sheet Seeds và Summary tự tổng hợp.
A4: Quy ước màu
B5: Ô vàng: bạn điền (cấu hình và kết quả đo).
A6: abc | B6: Chữ xanh dương: giá trị đã điền sẵn cho dòng baseline; bạn có thể sửa.
B7: Ô xám: công thức tự tính. Không sửa.
A9: Cách dùng
A10: 1. Sheet Experiments: dòng đầu là baseline mẫu. Điền lr và kết quả; thêm dòng cho mỗi thí nghiệm khác.
A11: 2. Mỗi dòng phải có ảnh riêng figures/<exp_id>.png. Điền tên file vào cột figure_file.
A12: 3. Sheet Seeds: nhập exp_id của các lần chạy baseline với seed khác nhau (đã gợi ý base-s1..3). Sheet tự tính trung bình, σ và 2σ.
A13: 4. Cột beyond_noise cho biết chênh lệch val_macro_f1 so với baseline có vượt 2σ không. Chỉ 'Có' mới là bằng chứng.
A14: 5. Sheet Summary: số dòng theo nhóm và số chủ đề (trong 7) đã được thử.
A16: Từ điển cột (sheet Experiments)
A17: Cột | B17: Ý nghĩa | C17: Cách điền
A18: exp_id | B18: Mã thí nghiệm, duy nhất; trùng tên file ảnh | C18: Tự đặt, ví dụ base-s1, opt-adam-lr1e-3, drop-0.3.
A19: group | B19: Nhóm: baseline | loss | optimizer | hparam | dropout | clipping | amp | init | final | other | C19: Chọn từ danh sách.
A20: description | B20: Bạn đổi gì so với baseline | C20: Một câu.
A21: loss | B21: Hàm mất mát: CE | MSE | C21: Chọn từ danh sách.
A22: optimizer | B22: SGD | SGD+momentum | Adam | AdamW | C22: Chọn từ danh sách.
A23: lr | B23: Tốc độ học η | C23: Ghi số, ví dụ 0.05 hoặc 1e-3.
A24: weight_decay | B24: Hệ số suy giảm trọng số λ | C24: 0 nếu không dùng.
A25: batch | B25: Kích thước lô | C25: Số nguyên.
A26: epochs | B26: Số epoch | C26: Khuyến nghị 20 cho mọi thí nghiệm.
A27: hidden | B27: Các lớp ẩn, ví dụ 256-128 | C27: Chuỗi nối bằng dấu gạch.
A28: dropout | B28: Xác suất tắt nơ-ron q | C28: 0 nếu không dùng.
... A33: step0_loss | B33: Loss trên val ở bước 0 (trước cập nhật đầu tiên) | C33: Kỳ vọng ≈ ln 7 = 1.946 nếu khởi tạo hợp lý.
A34: best_val_loss | B34: Val loss thấp nhất qua các epoch
A35: best_epoch | B35: Epoch đạt best_val_loss | C35: Đếm từ 1.
A36: final_train_loss | B36: Train loss ở epoch cuối (đo ở chế độ eval)
A37: final_val_loss | B37: Val loss ở epoch cuối
A38: val_acc | B38: Val accuracy ở best_epoch | C38: Phân số 0–1, ví dụ 0.8123.
A39: val_macro_f1 | B39: Val macro-F1 ở best_epoch | C39: Phân số 0–1.
A40: time_per_epoch_s | B40: Thời gian trung bình mỗi epoch (giây) | C40: Có torch.cuda.synchronize().
A41: peak_mem_MB | B41: Bộ nhớ GPU cực đại (MB) | C41: torch.cuda.max_memory_allocated()/2**20.
A42: diverged | B42: Loss thành NaN/inf? Y | N | C42: Chọn từ danh sách.
A43: eval_acc | B43: Accuracy trên tập eval | C43: CHỈ điền cho baseline và cấu hình cuối cùng, lấy từ eval_result.json.
A44: eval_macro_f1 | B44: macro-F1 trên tập eval | C44: CHỈ điền cho baseline và cấu hình cuối cùng, lấy từ eval_result.json.
A45: figure_file | B45: Tên file ảnh | C45: figures/<exp_id>.png
A46: notes | B46: Ghi chú | C46: Dự đoán trước, quan sát, lý do thiếu số liệu, lỗi gặp phải...
A47: step0_gap_vs_lnC | B47: step0_loss − ln 7 | C47: Tự tính. Gần 0 là tốt.
...

Sheet Experiments
A1: exp_id | B1: group | C1: description | D1: loss | E1: optimizer | F1: lr | G1: weight_decay | H1: batch | I1: epochs | J1: hidden | K1: dropout | L1: clip_norm | M1: precision | N1: init | O1: seed | P1: step0_loss | Q1: best_val_loss | R1: best_epoch | S1: final_train_loss | T1: final_val_loss | U1: val_acc | V1: val_macro_f1 | W1: time_per_epoch_s | X1: peak_mem_MB | Y1: diverged | Z1: eval_acc | AA1: eval_macro_f1 | AB1: figure_file | AC1: notes | AD1: step0_gap_vs_lnC | AE1: gap_val_minus_train | AF1: delta_val_f1_vs_base | AG1: beyond_noise
A2: amp-fp16 | B2: amp | C2: Controlled amp comparison | D2: ce | E2: sgd_momentum | F2: 0.05 | G2: 0 | H2: 512 | I2: 20 | J2: 256-128 | K2: 0 | L2: none | M2: fp16 | N2: he | O2: 1 | P2: 2.2690617 | Q2: 0.25221363 | R2: 19 | S2: 0.24942836 | T2: 0.26952913 | U2: 0.89764635 | V2: 0.83187267 | W2: 2.2833417 | X2: 159.41504 | Y2: FALSE | AB2: figures/amp-fp16.png | AC2: One factor changed relative to baseline; fixed seed 1.; activation_std=[0.3904455602169037, 0.36608922481536865, 0.5759302377700806]; mean clip_fraction=0.0 | AD2: =IF(P2="","",P2-LN(7)) -> 0.32315157 | AE2: =IF(OR(T2="",S2=""),"",T2-S2) -> 0.020100769 | AF2: =IF(OR(V2="",Seeds!$C$8=""),"",V2-Seeds!$C$8) -> -0.0087070774 | AG2: =IF(OR(AF2="",Seeds!$C$10=""),"",IF(ABS(AF2)>Seeds!$C$10,"Có","Không")) -> Kh?ng
A3: base-s1 | B3: baseline | C3: Baseline M-base | D3: ce | E3: sgd_momentum | F3: 0.05 | G3: 0 | H3: 512 | I3: 20 | J3: 256-128 | K3: 0 | L3: none | M3: fp32 | N3: he | O3: 1 | P3: 2.2690617 | Q3: 0.24606971 | R3: 19 | S3: 0.23903785 | T3: 0.26060369 | U3: 0.89989458 | V3: 0.84090009 | W3: 1.9837398 | X3: 159.41406 | Y3: FALSE | Z3: 0.89919365 | AA3: 0.84427799 | AB3: figures/base-s1.png | AC3: LR selected on validation; identical split seed 42.; BF16 skipped: no native hardware support; AMP comparison uses FP16. Majority val acc=0.487597083; health step0=2.269061720; overfit20 loss=0.000000631809, acc=1.0, updates=600; health/details in results/health.json. Diagnostics and initialization activation_std are stored in results JSON; peak includes resident data; time includes epoch evaluation.; activation_std=[0.3904455602169037, 0.36608922481536865, 0.5759302377700806]; mean clip_fraction=0.0 | AD3: =IF(P3="","",P3-LN(7)) -> 0.32315157 | AE3: =IF(OR(T3="",S3=""),"",T3-S3) -> 0.021565838 | AF3: =IF(OR(V3="",Seeds!$C$8=""),"",V3-Seeds!$C$8) -> 0.00032034492 | AG3: =IF(OR(AF3="",Seeds!$C$10=""),"",IF(ABS(AF3)>Seeds!$C$10,"Có","Không")) -> Kh?ng
A4: base-s2 | B4: baseline | C4: Baseline M-base | D4: ce | E4: sgd_momentum | F4: 0.05 | G4: 0 | H4: 512 | I4: 20 | J4: 256-128 | K4: 0 | L4: none | M4: fp32 | N4: he | O4: 2 | P4: 1.9781567 | Q4: 0.24850082 | R4: 20 | S4: 0.22657805 | T4: 0.24850082 | U4: 0.90117467 | V4: 0.83426716 | W4: 1.9829073 | X4: 159.41406 | Y4: FALSE | Z4: 0.9011041 | AA4: 0.84215352 | AB4: figures/base-s2.png | AC4: LR selected on validation; identical split seed 42.; activation_std=[0.40398284792900085, 0.40718355774879456, 0.5450341105461121]; mean clip_fraction=0.0 | AD4: =IF(P4="","",P4-LN(7)) -> 0.032246584 | AE4: =IF(OR(T4="",S4=""),"",T4-S4) -> 0.021922769 | AF4: =IF(OR(V4="",Seeds!$C$8=""),"",V4-Seeds!$C$8) -> -0.0063125917 | AG4: =IF(OR(AF4="",Seeds!$C$10=""),"",IF(ABS(AF4)>Seeds!$C$10,"Có","Không")) -> Kh?ng
A5: base-s3 | B5: baseline | C5: Baseline M-base | D5: ce | E5: sgd_momentum | F5: 0.05 | G5: 0 | H5: 512 | I5: 20 | J5: 256-128 | K5: 0 | L5: none | M5: fp32 | N5: he | O5: 3 | P5: 1.90054 | Q5: 0.23698231 | R5: 20 | S5: 0.21667564 | T5: 0.23698231 | U5: 0.90461694 | V5: 0.846572 | W5: 2.001571 | X5: 159.41406 | Y5: FALSE | Z5: 0.90340181 | AA5: 0.85121965 | AB5: figures/base-s3.png | AC5: LR selected on validation; identical split seed 42.; activation_std=[0.3927856683731079, 0.4206945300102234, 0.5369671583175659]; mean clip_fraction=0.0 | AD5: =IF(P5="","",P5-LN(7)) -> -0.045370143 | AE5: =IF(OR(T5="",S5=""),"",T5-S5) -> 0.020306667 | AF5: =IF(OR(V5="",Seeds!$C$8=""),"",V5-Seeds!$C$8) -> 0.0059922468 | AG5: =IF(OR(AF5="",Seeds!$C$10=""),"",IF(ABS(AF5)>Seeds!$C$10,"Có","Không")) -> Kh?ng
A6: clip-normal | B6: clipping | C6: Controlled clipping comparison | D6: ce | E6: sgd_momentum | F6: 0.05 | G6: 0 | H6: 512 | I6: 20 | J6: 256-128 | K6: 0 | L6: 0.38969307 | M6: fp32 | N6: he | O6: 1 | P6: 2.2690617 | Q6: 0.27552143 | R6: 19 | S6: 0.2715476 | T6: 0.28813853 | U6: 0.88687851 | V6: 0.80299107 | W6: 1.778565 | X6: 159.41406 | Y6: FALSE | AB6: figures/clip-normal.png | AC6: One factor changed relative to baseline; fixed seed 1.; activation_std=[0.3904455602169037, 0.36608922481536865, 0.5759302377700806]; mean clip_fraction=0.9945667117834092 | AD6: =IF(P6="","",P6-LN(7)) -> 0.32315157 | AE6: =IF(OR(T6="",S6=""),"",T6-S6) -> 0.016590928 | AF6: =IF(OR(V6="",Seeds!$C$8=""),"",V6-Seeds!$C$8) -> -0.037588683 | AG6: =IF(OR(AF6="",Seeds!$C$10=""),"",IF(ABS(AF6)>Seeds!$C$10,"Có","Không")) -> C?
A7: drop-0.3 | B7: dropout | C7: Controlled dropout comparison | D7: ce | E7: sgd_momentum | F7: 0.05 | G7: 0 | H7: 512 | I7: 20 | J7: 256-128 | K7: 0.3 | L7: none | M7: fp32 | N7: he | O7: 1 | P7: 2.2690617 | Q7: 0.33919301 | R7: 20 | S7: 0.33637016 | T7: 0.33919301 | U7: 0.86336352 | V7: 0.75193793 | W7: 1.9626655 | X7: 159.41406 | Y7: FALSE | AB7: figures/drop-0.3.png | AC7: One factor changed relative to baseline; fixed seed 1.; activation_std=[0.3904455602169037, 0.36608922481536865, 0.5759302377700806]; mean clip_fraction=0.0 | AD7: =IF(P7="","",P7-LN(7)) -> 0.32315157 | AE7: =IF(OR(T7="",S7=""),"",T7-S7) -> 0.0028228532 | AF7: =IF(OR(V7="",Seeds!$C$8=""),"",V7-Seeds!$C$8) -> -0.088641819 | AG7: =IF(OR(AF7="",Seeds!$C$10=""),"",IF(ABS(AF7)>Seeds!$C$10,"Có","Không")) -> C?
A8: final-s2 | B8: final | C8: Replica of validation-selected final configuration | D8: ce | E8: adam | F8: 0.003 | G8: 0 | H8: 512 | I8: 20 | J8: 256-128 | K8: 0 | L8: none | M8: fp32 | N8: he | O8: 2 | P8: 1.9781567 | Q8: 0.20583612 | R8: 20 | S8: 0.17559869 | T8: 0.20583612 | U8: 0.91807405 | V8: 0.87319315 | W8: 8.2966905 | X8: 159.59717 | Y8: FALSE | Z8: 0.91742898 | AA8: 0.87314096 | AB8: figures/final-s2.png | AC8: Same selected config as search-adam-lr0.003; seed changed only. Not selected using eval.; activation_std=[0.40398284792900085, 0.40718355774879456, 0.5450341105461121]; mean clip_fraction=0.0 | AD8: =IF(P8="","",P8-LN(7)) -> 0.032246584 | AE8: =IF(OR(T8="",S8=""),"",T8-S8) -> 0.03023743 | AF8: =IF(OR(V8="",Seeds!$C$8=""),"",V8-Seeds!$C$8) -> 0.032613399 | AG8: =IF(OR(AF8="",Seeds!$C$10=""),"",IF(ABS(AF8)>Seeds!$C$10,"Có","Không")) -> C?
A9: final-s3 | B9: final | C9: Replica of validation-selected final configuration | D9: ce | E9: adam | F9: 0.003 | G9: 0 | H9: 512 | I9: 20 | J9: 256-128 | K9: 0 | L9: none | M9: fp32 | N9: he | O9: 3 | P9: 1.90054 | Q9: 0.20593014 | R9: 20 | S9: 0.17591391 | T9: 0.20593014 | U9: 0.91860115 | V9: 0.87830495 | W9: 6.9584803 | X9: 159.59717 | Y9: FALSE | Z9: 0.91854771 | AA9: 0.88250072 | AB9: figures/final-s3.png | AC9: Same selected config as search-adam-lr0.003; seed changed only. Not selected using eval.; activation_std=[0.3927856683731079, 0.4206945300102234, 0.5369671583175659]; mean clip_fraction=0.0 | AD9: =IF(P9="","",P9-LN(7)) -> -0.045370143 | AE9: =IF(OR(T9="",S9=""),"",T9-S9) -> 0.030016234 | AF9: =IF(OR(V9="",Seeds!$C$8=""),"",V9-Seeds!$C$8) -> 0.037725201 | AG9: =IF(OR(AF9="",Seeds!$C$10=""),"",IF(ABS(AF9)>Seeds!$C$10,"Có","Không")) -> C?
A10: highlr-clip | B10: clipping | C10: Controlled clipping comparison | D10: ce | E10: sgd_momentum | F10: 0.5 | G10: 0 | H10: 512 | I10: 20 | J10: 256-128 | K10: 0 | L10: 0.38969307 | M10: fp32 | N10: he | O10: 1 | P10: 2.2690617 | Q10: 0.23530284 | R10: 19 | S10: 0.21358861 | T10: 0.24305643 | U10: 0.90701577 | V10: 0.85286102 | W10: 1.6829716 | X10: 159.41406 | Y10: FALSE | AB10: figures/highlr-clip.png | AC10: High-lr clipping pair changes lr relative to baseline; clip is the only difference within the pair.; activation_std=[0.3904455602169037, 0.36608922481536865, 0.5759302377700806]; mean clip_fraction=0.01980742806917988 | AD10: =IF(P10="","",P10-LN(7)) -> 0.32315157 | AE10: =IF(OR(T10="",S10=""),"",T10-S10) -> 0.029467815 | AF10: =IF(OR(V10="",Seeds!$C$8=""),"",V10-Seeds!$C$8) -> 0.012281275 | AG10: =IF(OR(AF10="",Seeds!$C$10=""),"",IF(ABS(AF10)>Seeds!$C$10,"Có","Không")) -> Kh?ng
A11: highlr-no-clip | B11: clipping | C11: Controlled clipping comparison | D11: ce | E11: sgd_momentum | F11: 0.5 | G11: 0 | H11: 512 | I11: 20 | J11: 256-128 | K11: 0 | L11: none | M11: fp32 | N11: he | O11: 1 | P11: 2.2690617 | Q11: 0.2541441 | R11: 19 | S11: 0.236744 | T11: 0.25777825 | U11: 0.89653837 | V11: 0.82475018 | W11: 1.7810729 | X11: 159.41406 | Y11: FALSE | AB11: figures/highlr-no-clip.png | AC11: High-lr clipping pair changes lr relative to baseline; clip is the only difference within the pair.; activation_std=[0.3904455602169037, 0.36608922481536865, 0.5759302377700806]; mean clip_fraction=0.0 | AD11: =IF(P11="","",P11-LN(7)) -> 0.32315157 | AE11: =IF(OR(T11="",S11=""),"",T11-S11) -> 0.02103425 | AF11: =IF(OR(V11="",Seeds!$C$8=""),"",V11-Seeds!$C$8) -> -0.015829568 | AG11: =IF(OR(AF11="",Seeds!$C$10=""),"",IF(ABS(AF11)>Seeds!$C$10,"Có","Không")) -> C?
A12: init-normal | B12: init | C12: Controlled init comparison | D12: ce | E12: sgd_momentum | F12: 0.05 | G12: 0 | H12: 512 | I12: 20 | J12: 256-128 | K12: 0 | L12: none | M12: fp32 | N12: normal | O12: 1 | P12: 1.9459957 | Q12: 0.27165846 | R12: 20 | S12: 0.25472871 | T12: 0.27165846 | U12: 0.88990125 | V12: 0.81421727 | W12: 1.7062921 | X12: 159.41406 | Y12: FALSE | AB12: figures/init-normal.png | AC12: One factor changed relative to baseline; fixed seed 1.; activation_std=[0.020288147032260895, 0.0021521563176065683, 0.0002708611136768013]; mean clip_fraction=0.0 | AD12: =IF(P12="","",P12-LN(7)) -> 8.5593829e-05 | AE12: =IF(OR(T12="",S12=""),"",T12-S12) -> 0.016929752 | AF12: =IF(OR(V12="",Seeds!$C$8=""),"",V12-Seeds!$C$8) -> -0.02636248 | AG12: =IF(OR(AF12="",Seeds!$C$10=""),"",IF(ABS(AF12)>Seeds!$C$10,"Có","Không")) -> C?
A13: init-xavier | B13: init | C13: Controlled init comparison | D13: ce | E13: sgd_momentum | F13: 0.05 | G13: 0 | H13: 512 | I13: 20 | J13: 256-128 | K13: 0 | L13: none | M13: fp32 | N13: xavier | O13: 1 | P13: 2.0221764 | Q13: 0.24728249 | R13: 19 | S13: 0.24698186 | T13: 0.26499266 | U13: 0.89918461 | V13: 0.83178749 | W13: 1.6871735 | X13: 159.41406 | Y13: FALSE | AB13: figures/init-xavier.png | AC13: One factor changed relative to baseline; fixed seed 1.; activation_std=[0.1629583090543747, 0.12475481629371643, 0.19110776484012604]; mean clip_fraction=0.0 | AD13: =IF(P13="","",P13-LN(7)) -> 0.076266251 | AE13: =IF(OR(T13="",S13=""),"",T13-S13) -> 0.018010809 | AF13: =IF(OR(V13="",Seeds!$C$8=""),"",V13-Seeds!$C$8) -> -0.0087922648 | AG13: =IF(OR(AF13="",Seeds!$C$10=""),"",IF(ABS(AF13)>Seeds!$C$10,"Có","Không")) -> Kh?ng
A14: init-zeros | B14: init | C14: Controlled init comparison | D14: ce | E14: sgd_momentum | F14: 0.05 | G14: 0 | H14: 512 | I14: 20 | J14: 256-128 | K14: 0 | L14: none | M14: fp32 | N14: zeros | O14: 1 | P14: 1.9459152 | Q14: 1.2051771 | R14: 8 | S14: 1.2018716 | T14: 1.205294 | U14: 0.48759708 | V14: 0.09364999 | W14: 1.7112117 | X14: 159.41406 | Y14: FALSE | AB14: figures/init-zeros.png | AC14: One factor changed relative to baseline; fixed seed 1.; activation_std=[0.0, 0.0, 0.0]; mean clip_fraction=0.0 | AD14: =IF(P14="","",P14-LN(7)) -> 5.0837818e-06 | AE14: =IF(OR(T14="",S14=""),"",T14-S14) -> 0.0034224185 | AF14: =IF(OR(V14="",Seeds!$C$8=""),"",V14-Seeds!$C$8) -> -0.74692976 | AG14: =IF(OR(AF14="",Seeds!$C$10=""),"",IF(ABS(AF14)>Seeds!$C$10,"Có","Không")) -> C?
A15: loss-mse | B15: loss | C15: Controlled loss comparison | D15: mse | E15: sgd_momentum | F15: 0.05 | G15: 0 | H15: 512 | I15: 20 | J15: 256-128 | K15: 0 | L15: none | M15: fp32 | N15: he | O15: 1 | P15: 0.63585041 | Q15: 0.032439811 | R15: 20 | S15: 0.031914426 | T15: 0.032439811 | U15: 0.85498376 | V15: 0.69111613 | W15: 2.0763423 | X15: 159.41748 | Y15: FALSE | AB15: figures/loss-mse.png | AC15: One factor changed relative to baseline; fixed seed 1.; activation_std=[0.3904455602169037, 0.36608922481536865, 0.5759302377700806]; mean clip_fraction=0.0 | AD15: =IF(P15="","",P15-LN(7)) -> -1.3100597 | AE15: =IF(OR(T15="",S15=""),"",T15-S15) -> 0.00052538438 | AF15: =IF(OR(V15="",Seeds!$C$8=""),"",V15-Seeds!$C$8) -> -0.14946362 | AG15: =IF(OR(AF15="",Seeds!$C$10=""),"",IF(ABS(AF15)>Seeds!$C$10,"Có","Không")) -> C?
A16: search-adam-lr0.0003 | B16: optimizer | C16: Validation LR search: adam, lr=0.0003 | D16: ce | E16: adam | F16: 0.0003 | G16: 0 | H16: 512 | I16: 20 | J16: 256-128 | K16: 0 | L16: none | M16: fp32 | N16: he | O16: 1 | P16: 2.2690617 | Q16: 0.31167011 | R16: 20 | S16: 0.30093973 | T16: 0.31167011 | U16: 0.87285127 | V16: 0.77943887 | W16: 1.9609426 | X16: 161.42578 | Y16: FALSE | AB16: figures/search-adam-lr0.0003.png | AC16: 20 epochs; optimizer and its learning rate calibrated together; fixed seed 1.; activation_std=[0.3904455602169037, 0.36608922481536865, 0.5759302377700806]; mean clip_fraction=0.0 | AD16: =IF(P16="","",P16-LN(7)) -> 0.32315157 | AE16: =IF(OR(T16="",S16=""),"",T16-S16) -> 0.010730381 | AF16: =IF(OR(V16="",Seeds!$C$8=""),"",V16-Seeds!$C$8) -> -0.061140876 | AG16: =IF(OR(AF16="",Seeds!$C$10=""),"",IF(ABS(AF16)>Seeds!$C$10,"Có","Không")) -> C?
A17: search-adam-lr0.001 | B17: optimizer | C17: Validation LR search: adam, lr=0.001 | D17: ce | E17: adam | F17: 0.001 | G17: 0 | H17: 512 | I17: 20 | J17: 256-128 | K17: 0 | L17: none | M17: fp32 | N17: he | O17: 1 | P17: 2.2690617 | Q17: 0.24155808 | R17: 20 | S17: 0.22378643 | T17: 0.24155808 | U17: 0.90418666 | V17: 0.84770767 | W17: 169.07138 | X17: 160.12402 | Y17: FALSE | AB17: figures/search-adam-lr0.001.png | AC17: 20 epochs; optimizer and its learning rate calibrated together; fixed seed 1.; Timing outlier: max epoch 3344.742s, median 1.922s; arithmetic mean retained, do not infer optimizer speed from this run.; activation_std=[0.3904455602169037, 0.36608922481536865, 0.5759302377700806]; mean clip_fraction=0.0 | AD17: =IF(P17="","",P17-LN(7)) -> 0.32315157 | AE17: =IF(OR(T17="",S17=""),"",T17-S17) -> 0.017771659 | AF17: =IF(OR(V17="",Seeds!$C$8=""),"",V17-Seeds!$C$8) -> 0.0071279225 | AG17: =IF(OR(AF17="",Seeds!$C$10=""),"",IF(ABS(AF17)>Seeds!$C$10,"Có","Không")) -> Kh?ng
A18: search-adam-lr0.003 | B18: optimizer | C18: Validation LR search: adam, lr=0.003 | D18: ce | E18: adam | F18: 0.003 | G18: 0 | H18: 512 | I18: 20 | J18: 256-128 | K18: 0 | L18: none | M18: fp32 | N18: he | O18: 1 | P18: 2.2690617 | Q18: 0.21128563 | R18: 20 | S18: 0.18336086 | T18: 0.21128563 | U18: 0.91661109 | V18: 0.86564733 | W18: 2.5052986 | X18: 160.12402 | Y18: FALSE | Z18: 0.91495917 | AA18: 0.86397533 | AB18: figures/search-adam-lr0.003.png | AC18: 20 epochs; optimizer and its learning rate calibrated together; fixed seed 1.; activation_std=[0.3904455602169037, 0.36608922481536865, 0.5759302377700806]; mean clip_fraction=0.0 | AD18: =IF(P18="","",P18-LN(7)) -> 0.32315157 | AE18: =IF(OR(T18="",S18=""),"",T18-S18) -> 0.027924775 | AF18: =IF(OR(V18="",Seeds!$C$8=""),"",V18-Seeds!$C$8) -> 0.025067577 | AG18: =IF(OR(AF18="",Seeds!$C$10=""),"",IF(ABS(AF18)>Seeds!$C$10,"Có","Không")) -> C?
A19: search-sgd_momentum-lr0.01 | B19: optimizer | C19: Validation LR search: sgd_momentum, lr=0.01 | D19: ce | E19: sgd_momentum | F19: 0.01 | G19: 0 | H19: 512 | I19: 20 | J19: 256-128 | K19: 0 | L19: none | M19: fp32 | N19: he | O19: 1 | P19: 2.2690617 | Q19: 0.32269398 | R19: 19 | S19: 0.33253922 | T19: 0.343688 | U19: 0.86710699 | V19: 0.75603478 | W19: 1.8499797 | X19: 161.24268 | Y19: FALSE | AB19: figures/search-sgd_momentum-lr0.01.png | AC19: 20 epochs; optimizer and its learning rate calibrated together; fixed seed 1.; activation_std=[0.3904455602169037, 0.36608922481536865, 0.5759302377700806]; mean clip_fraction=0.0 | AD19: =IF(P19="","",P19-LN(7)) -> 0.32315157 | AE19: =IF(OR(T19="",S19=""),"",T19-S19) -> 0.011148781 | AF19: =IF(OR(V19="",Seeds!$C$8=""),"",V19-Seeds!$C$8) -> -0.084544972 | AG19: =IF(OR(AF19="",Seeds!$C$10=""),"",IF(ABS(AF19)>Seeds!$C$10,"Có","Không")) -> C?
A20: search-sgd_momentum-lr0.05 | B20: optimizer | C20: Validation LR search: sgd_momentum, lr=0.05 | D20: ce | E20: sgd_momentum | F20: 0.05 | G20: 0 | H20: 512 | I20: 20 | J20: 256-128 | K20: 0 | L20: none | M20: fp32 | N20: he | O20: 1 | P20: 2.2690617 | Q20: 0.24606971 | R20: 19 | S20: 0.23903785 | T20: 0.26060369 | U20: 0.89989458 | V20: 0.84090009 | W20: 1.8297485 | X20: 161.24268 | Y20: FALSE | AB20: figures/search-sgd_momentum-lr0.05.png | AC20: 20 epochs; optimizer and its learning rate calibrated together; fixed seed 1.; activation_std=[0.3904455602169037, 0.36608922481536865, 0.5759302377700806]; mean clip_fraction=0.0 | AD20: =IF(P20="","",P20-LN(7)) -> 0.32315157 | AE20: =IF(OR(T20="",S20=""),"",T20-S20) -> 0.021565838 | AF20: =IF(OR(V20="",Seeds!$C$8=""),"",V20-Seeds!$C$8) -> 0.00032034492 | AG20: =IF(OR(AF20="",Seeds!$C$10=""),"",IF(ABS(AF20)>Seeds!$C$10,"Có","Không")) -> Kh?ng
A21: search-sgd_momentum-lr0.1 | B21: optimizer | C21: Validation LR search: sgd_momentum, lr=0.1 | D21: ce | E21: sgd_momentum | F21: 0.1 | G21: 0 | H21: 512 | I21: 20 | J21: 256-128 | K21: 0 | L21: none | M21: fp32 | N21: he | O21: 1 | P21: 2.2690617 | Q21: 0.23173124 | R21: 20 | S21: 0.20855816 | T21: 0.23173124 | U21: 0.90732773 | V21: 0.83945996 | W21: 1.8190754 | X21: 161.24268 | Y21: FALSE | AB21: figures/search-sgd_momentum-lr0.1.png | AC21: 20 epochs; optimizer and its learning rate calibrated together; fixed seed 1.; activation_std=[0.3904455602169037, 0.36608922481536865, 0.5759302377700806]; mean clip_fraction=0.0 | AD21: =IF(P21="","",P21-LN(7)) -> 0.32315157 | AE21: =IF(OR(T21="",S21=""),"",T21-S21) -> 0.023173073 | AF21: =IF(OR(V21="",Seeds!$C$8=""),"",V21-Seeds!$C$8) -> -0.0011197945 | AG21: =IF(OR(AF21="",Seeds!$C$10=""),"",IF(ABS(AF21)>Seeds!$C$10,"Có","Không")) -> Kh?ng
A22: wide | B22: hparam | C22: Controlled hparam comparison | D22: ce | E22: sgd_momentum | F22: 0.05 | G22: 0 | H22: 512 | I22: 20 | J22: 512-256 | K22: 0 | L22: none | M22: fp32 | N22: he | O22: 1 | P22: 1.9182166 | Q22: 0.21485797 | R22: 20 | S22: 0.18807398 | T22: 0.21485797 | U22: 0.91341623 | V22: 0.84881482 | W22: 1.7490948 | X22: 175.73633 | Y22: FALSE | AB22: figures/wide.png | AC22: One factor changed relative to baseline; fixed seed 1.; activation_std=[0.38286158442497253, 0.36626678705215454, 0.5286765098571777]; mean clip_fraction=0.0 | AD22: =IF(P22="","",P22-LN(7)) -> -0.027693566 | AE22: =IF(OR(T22="",S22=""),"",T22-S22) -> 0.026783989 | AF22: =IF(OR(V22="",Seeds!$C$8=""),"",V22-Seeds!$C$8) -> 0.0082350746 | AG22: =IF(OR(AF22="",Seeds!$C$10=""),"",IF(ABS(AF22)>Seeds!$C$10,"Có","Không")) -> Kh?ng
AD23: =IF(P23="","",P23-LN(7)) | AE23: =IF(OR(T23="",S23=""),"",T23-S23) | AF23: =IF(OR(V23="",Seeds!$C$8=""),"",V23-Seeds!$C$8) | AG23: =IF(OR(AF23="",Seeds!$C$10=""),"",IF(ABS(AF23)>Seeds!$C$10,"Có","Không"))
AD24: =IF(P24="","",P24-LN(7)) | AE24: =IF(OR(T24="",S24=""),"",T24-S24) | AF24: =IF(OR(V24="",Seeds!$C$8=""),"",V24-Seeds!$C$8) | AG24: =IF(OR(AF24="",Seeds!$C$10=""),"",IF(ABS(AF24)>Seeds!$C$10,"Có","Không"))
AD25: =IF(P25="","",P25-LN(7)) | AE25: =IF(OR(T25="",S25=""),"",T25-S25) | AF25: =IF(OR(V25="",Seeds!$C$8=""),"",V25-Seeds!$C$8) | AG25: =IF(OR(AF25="",Seeds!$C$10=""),"",IF(ABS(AF25)>Seeds!$C$10,"Có","Không"))
AD26: =IF(P26="","",P26-LN(7)) | AE26: =IF(OR(T26="",S26=""),"",T26-S26) | AF26: =IF(OR(V26="",Seeds!$C$8=""),"",V26-Seeds!$C$8) | AG26: =IF(OR(AF26="",Seeds!$C$10=""),"",IF(ABS(AF26)>Seeds!$C$10,"Có","Không"))
AD27: =IF(P27="","",P27-LN(7)) | AE27: =IF(OR(T27="",S27=""),"",T27-S27) | AF27: =IF(OR(V27="",Seeds!$C$8=""),"",V27-Seeds!$C$8) | AG27: =IF(OR(AF27="",Seeds!$C$10=""),"",IF(ABS(AF27)>Seeds!$C$10,"Có","Không"))
AD28: =IF(P28="","",P28-LN(7)) | AE28: =IF(OR(T28="",S28=""),"",T28-S28) | AF28: =IF(OR(V28="",Seeds!$C$8=""),"",V28-Seeds!$C$8) | AG28: =IF(OR(AF28="",Seeds!$C$10=""),"",IF(ABS(AF28)>Seeds!$C$10,"Có","Không"))
AD29: =IF(P29="","",P29-LN(7)) | AE29: =IF(OR(T29="",S29=""),"",T29-S29) | AF29: =IF(OR(V29="",Seeds!$C$8=""),"",V29-Seeds!$C$8) | AG29: =IF(OR(AF29="",Seeds!$C$10=""),"",IF(ABS(AF29)>Seeds!$C$10,"Có","Không"))
AD30: =IF(P30="","",P30-LN(7)) | AE30: =IF(OR(T30="",S30=""),"",T30-S30) | AF30: =IF(OR(V30="",Seeds!$C$8=""),"",V30-Seeds!$C$8) | AG30: =IF(OR(AF30="",Seeds!$C$10=""),"",IF(ABS(AF30)>Seeds!$C$10,"Có","Không"))
AD31: =IF(P31="","",P31-LN(7)) | AE31: =IF(OR(T31="",S31=""),"",T31-S31) | AF31: =IF(OR(V31="",Seeds!$C$8=""),"",V31-Seeds!$C$8) | AG31: =IF(OR(AF31="",Seeds!$C$10=""),"",IF(ABS(AF31)>Seeds!$C$10,"Có","Không"))
AD32: =IF(P32="","",P32-LN(7)) | AE32: =IF(OR(T32="",S32=""),"",T32-S32) | AF32: =IF(OR(V32="",Seeds!$C$8=""),"",V32-Seeds!$C$8) | AG32: =IF(OR(AF32="",Seeds!$C$10=""),"",IF(ABS(AF32)>Seeds!$C$10,"Có","Không"))
AD33: =IF(P33="","",P33-LN(7)) | AE33: =IF(OR(T33="",S33=""),"",T33-S33) | AF33: =IF(OR(V33="",Seeds!$C$8=""),"",V33-Seeds!$C$8) | AG33: =IF(OR(AF33="",Seeds!$C$10=""),"",IF(ABS(AF33)>Seeds!$C$10,"Có","Không"))
AD34: =IF(P34="","",P34-LN(7)) | AE34: =IF(OR(T34="",S34=""),"",T34-S34) | AF34: =IF(OR(V34="",Seeds!$C$8=""),"",V34-Seeds!$C$8) | AG34: =IF(OR(AF34="",Seeds!$C$10=""),"",IF(ABS(AF34)>Seeds!$C$10,"Có","Không"))
... AD61: =IF(P61="","",P61-LN(7)) | AE61: =IF(OR(T61="",S61=""),"",T61-S61) | AF61: =IF(OR(V61="",Seeds!$C$8=""),"",V61-Seeds!$C$8) | AG61: =IF(OR(AF61="",Seeds!$C$10=""),"",IF(ABS(AF61)>Seeds!$C$10,"Có","Không"))

Sheet Seeds
A1: exp_id baseline (nhập) | B1: val_acc | C1: val_macro_f1 | D1: best_val_loss
A2: base-s1 | B2: =IF($A2="","",IFERROR(IF(INDEX(Experiments!$U$2:$U$61,MATCH($A2,Experiments!$A$2:$A$61,0))="","",INDEX(Experiments!$U$2:$U$61,MATCH($A2,Experiments!$A$2:$A$61,0))),"")) -> 0.89989458 | C2: =IF($A2="","",IFERROR(IF(INDEX(Experiments!$V$2:$V$61,MATCH($A2,Experiments!$A$2:$A$61,0))="","",INDEX(Experiments!$V$2:$V$61,MATCH($A2,Experiments!$A$2:$A$61,0))),"")) -> 0.84090009 | D2: =IF($A2="","",IFERROR(IF(INDEX(Experiments!$Q$2:$Q$61,MATCH($A2,Experiments!$A$2:$A$61,0))="","",INDEX(Experiments!$Q$2:$Q$61,MATCH($A2,Experiments!$A$2:$A$61,0))),"")) -> 0.24606971
A3: base-s2 | B3: =IF($A3="","",IFERROR(IF(INDEX(Experiments!$U$2:$U$61,MATCH($A3,Experiments!$A$2:$A$61,0))="","",INDEX(Experiments!$U$2:$U$61,MATCH($A3,Experiments!$A$2:$A$61,0))),"")) -> 0.90117467 | C3: =IF($A3="","",IFERROR(IF(INDEX(Experiments!$V$2:$V$61,MATCH($A3,Experiments!$A$2:$A$61,0))="","",INDEX(Experiments!$V$2:$V$61,MATCH($A3,Experiments!$A$2:$A$61,0))),"")) -> 0.83426716 | D3: =IF($A3="","",IFERROR(IF(INDEX(Experiments!$Q$2:$Q$61,MATCH($A3,Experiments!$A$2:$A$61,0))="","",INDEX(Experiments!$Q$2:$Q$61,MATCH($A3,Experiments!$A$2:$A$61,0))),"")) -> 0.24850082
A4: base-s3 | B4: =IF($A4="","",IFERROR(IF(INDEX(Experiments!$U$2:$U$61,MATCH($A4,Experiments!$A$2:$A$61,0))="","",INDEX(Experiments!$U$2:$U$61,MATCH($A4,Experiments!$A$2:$A$61,0))),"")) -> 0.90461694 | C4: =IF($A4="","",IFERROR(IF(INDEX(Experiments!$V$2:$V$61,MATCH($A4,Experiments!$A$2:$A$61,0))="","",INDEX(Experiments!$V$2:$V$61,MATCH($A4,Experiments!$A$2:$A$61,0))),"")) -> 0.846572 | D4: =IF($A4="","",IFERROR(IF(INDEX(Experiments!$Q$2:$Q$61,MATCH($A4,Experiments!$A$2:$A$61,0))="","",INDEX(Experiments!$Q$2:$Q$61,MATCH($A4,Experiments!$A$2:$A$61,0))),"")) -> 0.23698231
B5: =IF($A5="","",IFERROR(IF(INDEX(Experiments!$U$2:$U$61,MATCH($A5,Experiments!$A$2:$A$61,0))="","",INDEX(Experiments!$U$2:$U$61,MATCH($A5,Experiments!$A$2:$A$61,0))),"")) | C5: =IF($A5="","",IFERROR(IF(INDEX(Experiments!$V$2:$V$61,MATCH($A5,Experiments!$A$2:$A$61,0))="","",INDEX(Experiments!$V$2:$V$61,MATCH($A5,Experiments!$A$2:$A$61,0))),"")) | D5: =IF($A5="","",IFERROR(IF(INDEX(Experiments!$Q$2:$Q$61,MATCH($A5,Experiments!$A$2:$A$61,0))="","",INDEX(Experiments!$Q$2:$Q$61,MATCH($A5,Experiments!$A$2:$A$61,0))),""))
B6: =IF($A6="","",IFERROR(IF(INDEX(Experiments!$U$2:$U$61,MATCH($A6,Experiments!$A$2:$A$61,0))="","",INDEX(Experiments!$U$2:$U$61,MATCH($A6,Experiments!$A$2:$A$61,0))),"")) | C6: =IF($A6="","",IFERROR(IF(INDEX(Experiments!$V$2:$V$61,MATCH($A6,Experiments!$A$2:$A$61,0))="","",INDEX(Experiments!$V$2:$V$61,MATCH($A6,Experiments!$A$2:$A$61,0))),"")) | D6: =IF($A6="","",IFERROR(IF(INDEX(Experiments!$Q$2:$Q$61,MATCH($A6,Experiments!$A$2:$A$61,0))="","",INDEX(Experiments!$Q$2:$Q$61,MATCH($A6,Experiments!$A$2:$A$61,0))),""))
A8: mean | B8: =IF(COUNT(B2:B6)=0,"",AVERAGE(B2:B6)) -> 0.9018954 | C8: =IF(COUNT(C2:C6)=0,"",AVERAGE(C2:C6)) -> 0.84057975 | D8: =IF(COUNT(D2:D6)=0,"",AVERAGE(D2:D6)) -> 0.24385095
A9: std (mẫu) | B9: =IF(COUNT(B2:B6)<2,"",STDEV(B2:B6)) -> 0.0024422844 | C9: =IF(COUNT(C2:C6)<2,"",STDEV(C2:C6)) -> 0.006158671 | D9: =IF(COUNT(D2:D6)<2,"",STDEV(D2:D6)) -> 0.0060713411
A10: 2σ (ngưỡng nhiễu) | B10: =IF(B9="","",2*B9) -> 0.0048845688 | C10: =IF(C9="","",2*C9) -> 0.012317342 | D10: =IF(D9="","",2*D9) -> 0.012142682
A12: Nhập exp_id của các lần chạy baseline (khác seed) ở cột A. Cần ≥ 2 seed để có σ.
A13: Mọi chênh lệch nhỏ hơn 2σ không được coi là bằng chứng. Với ít seed, σ chỉ là ước lượng thô; nêu rõ trong báo cáo.

Sheet Summary
A1: group | B1: số dòng | C1: đã điền val_macro_f1 | D1: val_macro_f1 cao nhất | E1: val_macro_f1 thấp nhất | F1: val_acc cao nhất | G1: đã thử chủ đề này? | H1: nhận xét ngắn (bạn viết)
A2: baseline | B2: =COUNTIF(Experiments!$B$2:$B$61,A2) -> 3 | C2: =COUNTIFS(Experiments!$B$2:$B$61,A2,Experiments!$V$2:$V$61,"<>") -> 3 | D2: =IF(C2=0,"",_xlfn.MAXIFS(Experiments!$V$2:$V$61,Experiments!$B$2:$B$61,A2)) -> 0.846572 | E2: =IF(C2=0,"",_xlfn.MINIFS(Experiments!$V$2:$V$61,Experiments!$B$2:$B$61,A2)) -> 0.83426716 | F2: =IF(C2=0,"",_xlfn.MAXIFS(Experiments!$U$2:$U$61,Experiments!$B$2:$B$61,A2)) -> 0.90461694 | G2: — | H2: Best measured validation F1: base-s3 (0.8466); consult report for seed limitations.
A3: loss | B3: =COUNTIF(Experiments!$B$2:$B$61,A3) -> 1 | C3: =COUNTIFS(Experiments!$B$2:$B$61,A3,Experiments!$V$2:$V$61,"<>") -> 1 | D3: =IF(C3=0,"",_xlfn.MAXIFS(Experiments!$V$2:$V$61,Experiments!$B$2:$B$61,A3)) -> 0.69111613 | E3: =IF(C3=0,"",_xlfn.MINIFS(Experiments!$V$2:$V$61,Experiments!$B$2:$B$61,A3)) -> 0.69111613 | F3: =IF(C3=0,"",_xlfn.MAXIFS(Experiments!$U$2:$U$61,Experiments!$B$2:$B$61,A3)) -> 0.85498376 | G3: =IF(C3>0,"Có","Chưa") -> C? | H3: Best measured validation F1: loss-mse (0.6911); consult report for seed limitations.
A4: optimizer | B4: =COUNTIF(Experiments!$B$2:$B$61,A4) -> 6 | C4: =COUNTIFS(Experiments!$B$2:$B$61,A4,Experiments!$V$2:$V$61,"<>") -> 6 | D4: =IF(C4=0,"",_xlfn.MAXIFS(Experiments!$V$2:$V$61,Experiments!$B$2:$B$61,A4)) -> 0.86564733 | E4: =IF(C4=0,"",_xlfn.MINIFS(Experiments!$V$2:$V$61,Experiments!$B$2:$B$61,A4)) -> 0.75603478 | F4: =IF(C4=0,"",_xlfn.MAXIFS(Experiments!$U$2:$U$61,Experiments!$B$2:$B$61,A4)) -> 0.91661109 | G4: =IF(C4>0,"Có","Chưa") -> C? | H4: Best measured validation F1: search-adam-lr0.003 (0.8656); consult report for seed limitations.
A5: hparam | B5: =COUNTIF(Experiments!$B$2:$B$61,A5) -> 1 | C5: =COUNTIFS(Experiments!$B$2:$B$61,A5,Experiments!$V$2:$V$61,"<>") -> 1 | D5: =IF(C5=0,"",_xlfn.MAXIFS(Experiments!$V$2:$V$61,Experiments!$B$2:$B$61,A5)) -> 0.84881482 | E5: =IF(C5=0,"",_xlfn.MINIFS(Experiments!$V$2:$V$61,Experiments!$B$2:$B$61,A5)) -> 0.84881482 | F5: =IF(C5=0,"",_xlfn.MAXIFS(Experiments!$U$2:$U$61,Experiments!$B$2:$B$61,A5)) -> 0.91341623 | G5: =IF(C5>0,"Có","Chưa") -> C? | H5: Best measured validation F1: wide (0.8488); consult report for seed limitations.
A6: dropout | B6: =COUNTIF(Experiments!$B$2:$B$61,A6) -> 1 | C6: =COUNTIFS(Experiments!$B$2:$B$61,A6,Experiments!$V$2:$V$61,"<>") -> 1 | D6: =IF(C6=0,"",_xlfn.MAXIFS(Experiments!$V$2:$V$61,Experiments!$B$2:$B$61,A6)) -> 0.75193793 | E6: =IF(C6=0,"",_xlfn.MINIFS(Experiments!$V$2:$V$61,Experiments!$B$2:$B$61,A6)) -> 0.75193793 | F6: =IF(C6=0,"",_xlfn.MAXIFS(Experiments!$U$2:$U$61,Experiments!$B$2:$B$61,A6)) -> 0.86336352 | G6: =IF(C6>0,"Có","Chưa") -> C? | H6: Best measured validation F1: drop-0.3 (0.7519); consult report for seed limitations.
A7: clipping | B7: =COUNTIF(Experiments!$B$2:$B$61,A7) -> 3 | C7: =COUNTIFS(Experiments!$B$2:$B$61,A7,Experiments!$V$2:$V$61,"<>") -> 3 | D7: =IF(C7=0,"",_xlfn.MAXIFS(Experiments!$V$2:$V$61,Experiments!$B$2:$B$61,A7)) -> 0.85286102 | E7: =IF(C7=0,"",_xlfn.MINIFS(Experiments!$V$2:$V$61,Experiments!$B$2:$B$61,A7)) -> 0.80299107 | F7: =IF(C7=0,"",_xlfn.MAXIFS(Experiments!$U$2:$U$61,Experiments!$B$2:$B$61,A7)) -> 0.90701577 | G7: =IF(C7>0,"Có","Chưa") -> C? | H7: Best measured validation F1: highlr-clip (0.8529); consult report for seed limitations.
A8: amp | B8: =COUNTIF(Experiments!$B$2:$B$61,A8) -> 1 | C8: =COUNTIFS(Experiments!$B$2:$B$61,A8,Experiments!$V$2:$V$61,"<>") -> 1 | D8: =IF(C8=0,"",_xlfn.MAXIFS(Experiments!$V$2:$V$61,Experiments!$B$2:$B$61,A8)) -> 0.83187267 | E8: =IF(C8=0,"",_xlfn.MINIFS(Experiments!$V$2:$V$61,Experiments!$B$2:$B$61,A8)) -> 0.83187267 | F8: =IF(C8=0,"",_xlfn.MAXIFS(Experiments!$U$2:$U$61,Experiments!$B$2:$B$61,A8)) -> 0.89764635 | G8: =IF(C8>0,"Có","Chưa") -> C? | H8: Best measured validation F1: amp-fp16 (0.8319); consult report for seed limitations.
A9: init | B9: =COUNTIF(Experiments!$B$2:$B$61,A9) -> 3 | C9: =COUNTIFS(Experiments!$B$2:$B$61,A9,Experiments!$V$2:$V$61,"<>") -> 3 | D9: =IF(C9=0,"",_xlfn.MAXIFS(Experiments!$V$2:$V$61,Experiments!$B$2:$B$61,A9)) -> 0.83178749 | E9: =IF(C9=0,"",_xlfn.MINIFS(Experiments!$V$2:$V$61,Experiments!$B$2:$B$61,A9)) -> 0.09364999 | F9: =IF(C9=0,"",_xlfn.MAXIFS(Experiments!$U$2:$U$61,Experiments!$B$2:$B$61,A9)) -> 0.89918461 | G9: =IF(C9>0,"Có","Chưa") -> C? | H9: Best measured validation F1: init-xavier (0.8318); consult report for seed limitations.
A10: final | B10: =COUNTIF(Experiments!$B$2:$B$61,A10) -> 2 | C10: =COUNTIFS(Experiments!$B$2:$B$61,A10,Experiments!$V$2:$V$61,"<>") -> 2 | D10: =IF(C10=0,"",_xlfn.MAXIFS(Experiments!$V$2:$V$61,Experiments!$B$2:$B$61,A10)) -> 0.87830495 | E10: =IF(C10=0,"",_xlfn.MINIFS(Experiments!$V$2:$V$61,Experiments!$B$2:$B$61,A10)) -> 0.87319315 | F10: =IF(C10=0,"",_xlfn.MAXIFS(Experiments!$U$2:$U$61,Experiments!$B$2:$B$61,A10)) -> 0.91860115 | G10: — | H10: Best measured validation F1: final-s3 (0.8783); consult report for seed limitations.
A11: other | B11: =COUNTIF(Experiments!$B$2:$B$61,A11) -> 0 | C11: =COUNTIFS(Experiments!$B$2:$B$61,A11,Experiments!$V$2:$V$61,"<>") -> 0 | D11: =IF(C11=0,"",_xlfn.MAXIFS(Experiments!$V$2:$V$61,Experiments!$B$2:$B$61,A11)) | E11: =IF(C11=0,"",_xlfn.MINIFS(Experiments!$V$2:$V$61,Experiments!$B$2:$B$61,A11)) | F11: =IF(C11=0,"",_xlfn.MAXIFS(Experiments!$U$2:$U$61,Experiments!$B$2:$B$61,A11)) | G11: —
A13: Số chủ đề (trong 7) đã thử: | D13: =COUNTIF(G2:G11,"Có")
A14: 7 chủ đề: loss, optimizer, hparam, dropout, clipping, amp, init. Một chủ đề 'đã thử' khi có ≥ 1 dòng có val_macro_f1.
